<mujoco model="panda">
    <actuator>
        
        <motor ctrllimited="false" forcelimited="false" joint="robot0_joint1" name="robot0_torq_j1" />
        <motor ctrllimited="false" forcelimited="false" joint="robot0_joint2" name="robot0_torq_j2" />
        <motor ctrllimited="false" forcelimited="false" joint="robot0_joint3" name="robot0_torq_j3" />
        <motor ctrllimited="false" forcelimited="false" joint="robot0_joint4" name="robot0_torq_j4" />
        <motor ctrllimited="false" forcelimited="false" joint="robot0_joint5" name="robot0_torq_j5" />
        <motor ctrllimited="false" forcelimited="false" joint="robot0_joint6" name="robot0_torq_j6" />
        <motor ctrllimited="false" forcelimited="false" joint="robot0_joint7" name="robot0_torq_j7" />
    <general name="gripper0_fingers_actuator" tendon="gripper0_split" forcerange="-5 5" ctrlrange="0 255" gainprm="0.3137255 0 0" biasprm="0 -100 -10" biastype="affine" />
  </actuator>
    <asset>
        <mesh name="robot0_link0" file="/juno/u/lepertm/shadow/robosuite/robosuite/models/assets/robots/panda/meshes/link0.stl" />
        <mesh name="robot0_link1" file="/juno/u/lepertm/shadow/robosuite/robosuite/models/assets/robots/panda/meshes/link1.stl" />
        <mesh name="robot0_link2" file="/juno/u/lepertm/shadow/robosuite/robosuite/models/assets/robots/panda/meshes/link2.stl" />
        <mesh name="robot0_link3" file="/juno/u/lepertm/shadow/robosuite/robosuite/models/assets/robots/panda/meshes/link3.stl" />
        <mesh name="robot0_link4" file="/juno/u/lepertm/shadow/robosuite/robosuite/models/assets/robots/panda/meshes/link4.stl" />
        <mesh name="robot0_link5" file="/juno/u/lepertm/shadow/robosuite/robosuite/models/assets/robots/panda/meshes/link5.stl" />
        <mesh name="robot0_link6" file="/juno/u/lepertm/shadow/robosuite/robosuite/models/assets/robots/panda/meshes/link6.stl" />
        <mesh name="robot0_link7" file="/juno/u/lepertm/shadow/robosuite/robosuite/models/assets/robots/panda/meshes/link7.stl" />

        
	<material name="robot0_Face636_001" specular="0.5" shininess="0.45" rgba="0.901961 0.921569 0.929412 1.000000" />
	<material name="robot0_Part__Feature017_001" specular="0.5" shininess="0.45" rgba="1.000000 1.000000 1.000000 1.000000" />
	<material name="robot0_Part__Feature018_001" specular="0.5" shininess="0.45" rgba="1.000000 1.000000 1.000000 1.000000" />
	<material name="robot0_Part__Feature019_001" specular="0.5" shininess="0.45" rgba="1.000000 1.000000 1.000000 1.000000" />
	<material name="robot0_Part__Feature022_001" specular="0.5" shininess="0.45" rgba="0.901961 0.921569 0.929412 1.000000" />
	<material name="robot0_Part__Feature023_001" specular="0.5" shininess="0.45" rgba="0.250980 0.250980 0.250980 1.000000" />
	<material name="robot0_Shell001_001" specular="0.5" shininess="0.45" rgba="0.250980 0.250980 0.250980 1.000000" />
	<material name="robot0_Shell002_001" specular="0.5" shininess="0.45" rgba="0.901961 0.921569 0.929412 1.000000" />
	<material name="robot0_Shell003_001" specular="0.5" shininess="0.45" rgba="0.901961 0.921569 0.929412 1.000000" />
	<material name="robot0_Shell009_001" specular="0.5" shininess="0.45" rgba="0.250980 0.250980 0.250980 1.000000" />
	<material name="robot0_Shell010_001" specular="0.5" shininess="0.45" rgba="0.901961 0.921569 0.929412 1.000000" />
	<material name="robot0_Shell_001" specular="0.5" shininess="0.45" rgba="0.250980 0.250980 0.250980 1.000000" />
	<mesh name="robot0_link0_vis_0" file="/juno/u/lepertm/shadow/robosuite/robosuite/models/assets/robots/panda/obj_meshes/link0_vis/link0_vis_0.obj" />
	<mesh name="robot0_link0_vis_1" file="/juno/u/lepertm/shadow/robosuite/robosuite/models/assets/robots/panda/obj_meshes/link0_vis/link0_vis_1.obj" />
	<mesh name="robot0_link0_vis_2" file="/juno/u/lepertm/shadow/robosuite/robosuite/models/assets/robots/panda/obj_meshes/link0_vis/link0_vis_2.obj" />
	<mesh name="robot0_link0_vis_3" file="/juno/u/lepertm/shadow/robosuite/robosuite/models/assets/robots/panda/obj_meshes/link0_vis/link0_vis_3.obj" />
	<mesh name="robot0_link0_vis_4" file="/juno/u/lepertm/shadow/robosuite/robosuite/models/assets/robots/panda/obj_meshes/link0_vis/link0_vis_4.obj" />
	<mesh name="robot0_link0_vis_5" file="/juno/u/lepertm/shadow/robosuite/robosuite/models/assets/robots/panda/obj_meshes/link0_vis/link0_vis_5.obj" />
	<mesh name="robot0_link0_vis_6" file="/juno/u/lepertm/shadow/robosuite/robosuite/models/assets/robots/panda/obj_meshes/link0_vis/link0_vis_6.obj" />
	<mesh name="robot0_link0_vis_7" file="/juno/u/lepertm/shadow/robosuite/robosuite/models/assets/robots/panda/obj_meshes/link0_vis/link0_vis_7.obj" />
	<mesh name="robot0_link0_vis_8" file="/juno/u/lepertm/shadow/robosuite/robosuite/models/assets/robots/panda/obj_meshes/link0_vis/link0_vis_8.obj" />
	<mesh name="robot0_link0_vis_9" file="/juno/u/lepertm/shadow/robosuite/robosuite/models/assets/robots/panda/obj_meshes/link0_vis/link0_vis_9.obj" />
	<mesh name="robot0_link0_vis_10" file="/juno/u/lepertm/shadow/robosuite/robosuite/models/assets/robots/panda/obj_meshes/link0_vis/link0_vis_10.obj" />
	<mesh name="robot0_link0_vis_11" file="/juno/u/lepertm/shadow/robosuite/robosuite/models/assets/robots/panda/obj_meshes/link0_vis/link0_vis_11.obj" />

        
	<material name="robot0_Part__Feature_001" specular="0.5" shininess="0.45" rgba="1.000000 1.000000 1.000000 1.000000" />
	<mesh name="robot0_link1_vis" file="/juno/u/lepertm/shadow/robosuite/robosuite/models/assets/robots/panda/obj_meshes/link1_vis/link1_vis.obj" />


        
	<material name="robot0_Part__Feature024" specular="0.5" shininess="0.45" rgba="1.000000 1.000000 1.000000 1.000000" />
	<mesh name="robot0_link2_vis" file="/juno/u/lepertm/shadow/robosuite/robosuite/models/assets/robots/panda/obj_meshes/link2_vis/link2_vis.obj" />

        
	<material name="robot0_Part__Feature001_010_001_002" specular="0.5" shininess="0.45" rgba="1.000000 1.000000 1.000000 1.000000" />
	<material name="robot0_Part__Feature002_007_001_002" specular="0.5" shininess="0.45" rgba="1.000000 1.000000 1.000000 1.000000" />
	<material name="robot0_Part__Feature003_004_001_002" specular="0.5" shininess="0.45" rgba="1.000000 1.000000 1.000000 1.000000" />
	<material name="robot0_Part__Feature_001_001_001_002" specular="0.5" shininess="0.45" rgba="0.250980 0.250980 0.250980 1.000000" />
	<mesh name="robot0_link3_vis_0" file="/juno/u/lepertm/shadow/robosuite/robosuite/models/assets/robots/panda/obj_meshes/link3_vis/link3_vis_0.obj" />
	<mesh name="robot0_link3_vis_1" file="/juno/u/lepertm/shadow/robosuite/robosuite/models/assets/robots/panda/obj_meshes/link3_vis/link3_vis_1.obj" />
	<mesh name="robot0_link3_vis_2" file="/juno/u/lepertm/shadow/robosuite/robosuite/models/assets/robots/panda/obj_meshes/link3_vis/link3_vis_2.obj" />
	<mesh name="robot0_link3_vis_3" file="/juno/u/lepertm/shadow/robosuite/robosuite/models/assets/robots/panda/obj_meshes/link3_vis/link3_vis_3.obj" />


        
	<material name="robot0_Part__Feature001_001_003_001" specular="0.5" shininess="0.45" rgba="1.000000 1.000000 1.000000 1.000000" />
	<material name="robot0_Part__Feature002_001_003_001" specular="0.5" shininess="0.45" rgba="0.250980 0.250980 0.250980 1.000000" />
	<material name="robot0_Part__Feature003_001_003_001" specular="0.5" shininess="0.45" rgba="1.000000 1.000000 1.000000 1.000000" />
	<material name="robot0_Part__Feature_002_003_001" specular="0.5" shininess="0.45" rgba="1.000000 1.000000 1.000000 1.000000" />
	<mesh name="robot0_link4_vis_0" file="/juno/u/lepertm/shadow/robosuite/robosuite/models/assets/robots/panda/obj_meshes/link4_vis/link4_vis_0.obj" />
	<mesh name="robot0_link4_vis_1" file="/juno/u/lepertm/shadow/robosuite/robosuite/models/assets/robots/panda/obj_meshes/link4_vis/link4_vis_1.obj" />
	<mesh name="robot0_link4_vis_2" file="/juno/u/lepertm/shadow/robosuite/robosuite/models/assets/robots/panda/obj_meshes/link4_vis/link4_vis_2.obj" />
	<mesh name="robot0_link4_vis_3" file="/juno/u/lepertm/shadow/robosuite/robosuite/models/assets/robots/panda/obj_meshes/link4_vis/link4_vis_3.obj" />

        
	<material name="robot0_Part__Feature_002_004_003" specular="0.5" shininess="0.45" rgba="1.000000 1.000000 1.000000 1.000000" />
	<material name="robot0_Shell001_001_001_003" specular="0.5" shininess="0.45" rgba="0.250000 0.250000 0.250000 1.000000" />
	<material name="robot0_Shell_001_001_003" specular="0.5" shininess="0.45" rgba="1.000000 1.000000 1.000000 1.000000" />
	<mesh name="robot0_link5_vis_0" file="/juno/u/lepertm/shadow/robosuite/robosuite/models/assets/robots/panda/obj_meshes/link5_vis/link5_vis_0.obj" />
	<mesh name="robot0_link5_vis_1" file="/juno/u/lepertm/shadow/robosuite/robosuite/models/assets/robots/panda/obj_meshes/link5_vis/link5_vis_1.obj" />
	<mesh name="robot0_link5_vis_2" file="/juno/u/lepertm/shadow/robosuite/robosuite/models/assets/robots/panda/obj_meshes/link5_vis/link5_vis_2.obj" />

        
	<material name="robot0_Face064_002_001_002_001" specular="0.5" shininess="0.45" rgba="1.000000 0.000000 0.000000 1.000000" />
	<material name="robot0_Face065_002_001_002_001" specular="0.5" shininess="0.45" rgba="0.000000 1.000000 0.000000 1.000000" />
	<material name="robot0_Face374_002_001_002_001" specular="0.5" shininess="0.45" rgba="1.000000 1.000000 1.000000 1.000000" />
	<material name="robot0_Face539_002_001_002_001" specular="0.5" shininess="0.45" rgba="0.250980 0.250980 0.250980 1.000000" />
	<material name="robot0_Part__Feature001_009_001_002_001" specular="0.5" shininess="0.45" rgba="0.250980 0.250980 0.250980 1.000000" />
	<material name="robot0_Part__Feature002_006_001_002_001" specular="0.5" shininess="0.45" rgba="0.250980 0.250980 0.250980 1.000000" />
	<material name="robot0_Shell002_002_001_002_001" specular="0.5" shininess="0.45" rgba="1.000000 1.000000 1.000000 1.000000" />
	<material name="robot0_Shell003_002_001_002_001" specular="0.5" shininess="0.45" rgba="1.000000 1.000000 1.000000 1.000000" />
	<material name="robot0_Shell004_001_001_002_001" specular="0.5" shininess="0.45" rgba="1.000000 1.000000 1.000000 1.000000" />
	<material name="robot0_Shell005_001_001_002_001" specular="0.5" shininess="0.45" rgba="1.000000 1.000000 1.000000 1.000000" />
	<material name="robot0_Shell006_003_002_001" specular="0.5" shininess="0.45" rgba="0.901961 0.921569 0.929412 1.000000" />
	<material name="robot0_Shell007_002_002_001" specular="0.5" shininess="0.45" rgba="0.250000 0.250000 0.250000 1.000000" />
	<material name="robot0_Shell011_002_002_001" specular="0.5" shininess="0.45" rgba="1.000000 1.000000 1.000000 1.000000" />
	<material name="robot0_Shell012_002_002_001" specular="0.5" shininess="0.45" rgba="1.000000 1.000000 1.000000 1.000000" />
	<material name="robot0_Shell_003_001_002_001" specular="0.5" shininess="0.45" rgba="0.250980 0.250980 0.250980 1.000000" />
	<material name="robot0_Union001_001_001_002_001" specular="0.5" shininess="0.45" rgba="0.039216 0.541176 0.780392 1.000000" />
	<material name="robot0_Union_001_001_002_001" specular="0.5" shininess="0.45" rgba="0.039216 0.541176 0.780392 1.000000" />	
	<mesh name="robot0_link6_vis_0" file="/juno/u/lepertm/shadow/robosuite/robosuite/models/assets/robots/panda/obj_meshes/link6_vis/link6_vis_0.obj" />
	<mesh name="robot0_link6_vis_1" file="/juno/u/lepertm/shadow/robosuite/robosuite/models/assets/robots/panda/obj_meshes/link6_vis/link6_vis_1.obj" />
	<mesh name="robot0_link6_vis_2" file="/juno/u/lepertm/shadow/robosuite/robosuite/models/assets/robots/panda/obj_meshes/link6_vis/link6_vis_2.obj" />
	<mesh name="robot0_link6_vis_3" file="/juno/u/lepertm/shadow/robosuite/robosuite/models/assets/robots/panda/obj_meshes/link6_vis/link6_vis_3.obj" />
	<mesh name="robot0_link6_vis_4" file="/juno/u/lepertm/shadow/robosuite/robosuite/models/assets/robots/panda/obj_meshes/link6_vis/link6_vis_4.obj" />
	<mesh name="robot0_link6_vis_5" file="/juno/u/lepertm/shadow/robosuite/robosuite/models/assets/robots/panda/obj_meshes/link6_vis/link6_vis_5.obj" />
	<mesh name="robot0_link6_vis_6" file="/juno/u/lepertm/shadow/robosuite/robosuite/models/assets/robots/panda/obj_meshes/link6_vis/link6_vis_6.obj" />
	<mesh name="robot0_link6_vis_7" file="/juno/u/lepertm/shadow/robosuite/robosuite/models/assets/robots/panda/obj_meshes/link6_vis/link6_vis_7.obj" />
	<mesh name="robot0_link6_vis_8" file="/juno/u/lepertm/shadow/robosuite/robosuite/models/assets/robots/panda/obj_meshes/link6_vis/link6_vis_8.obj" />
	<mesh name="robot0_link6_vis_9" file="/juno/u/lepertm/shadow/robosuite/robosuite/models/assets/robots/panda/obj_meshes/link6_vis/link6_vis_9.obj" />
	<mesh name="robot0_link6_vis_10" file="/juno/u/lepertm/shadow/robosuite/robosuite/models/assets/robots/panda/obj_meshes/link6_vis/link6_vis_10.obj" />
	<mesh name="robot0_link6_vis_11" file="/juno/u/lepertm/shadow/robosuite/robosuite/models/assets/robots/panda/obj_meshes/link6_vis/link6_vis_11.obj" />
	<mesh name="robot0_link6_vis_12" file="/juno/u/lepertm/shadow/robosuite/robosuite/models/assets/robots/panda/obj_meshes/link6_vis/link6_vis_12.obj" />
	<mesh name="robot0_link6_vis_13" file="/juno/u/lepertm/shadow/robosuite/robosuite/models/assets/robots/panda/obj_meshes/link6_vis/link6_vis_13.obj" />
	<mesh name="robot0_link6_vis_14" file="/juno/u/lepertm/shadow/robosuite/robosuite/models/assets/robots/panda/obj_meshes/link6_vis/link6_vis_14.obj" />
	<mesh name="robot0_link6_vis_15" file="/juno/u/lepertm/shadow/robosuite/robosuite/models/assets/robots/panda/obj_meshes/link6_vis/link6_vis_15.obj" />
	<mesh name="robot0_link6_vis_16" file="/juno/u/lepertm/shadow/robosuite/robosuite/models/assets/robots/panda/obj_meshes/link6_vis/link6_vis_16.obj" />

        
	<material name="robot0_Part__Mirroring001_004_002" specular="0.5" shininess="0.45" rgba="0.250980 0.250980 0.250980 1.000000" />
	<material name="robot0_Part__Mirroring002_004_001" specular="0.5" shininess="0.45" rgba="0.250980 0.250980 0.250980 1.000000" />
	<material name="robot0_Part__Mirroring003_004_001" specular="0.5" shininess="0.45" rgba="0.250980 0.250980 0.250980 1.000000" />
	<material name="robot0_Part__Mirroring004_004_002" specular="0.5" shininess="0.45" rgba="1.000000 1.000000 1.000000 1.000000" />
	<material name="robot0_Part__Mirroring005_004_001" specular="0.5" shininess="0.45" rgba="0.250980 0.250980 0.250980 1.000000" />
	<material name="robot0_Part__Mirroring006_004_001" specular="0.5" shininess="0.45" rgba="0.250980 0.250980 0.250980 1.000000" />
	<material name="robot0_Part__Mirroring007_004_001" specular="0.5" shininess="0.45" rgba="0.250980 0.250980 0.250980 1.000000" />
	<material name="robot0_Part__Mirroring_004_001" specular="0.5" shininess="0.45" rgba="0.898039 0.917647 0.929412 1.000000" />	

	<mesh name="robot0_link7_vis_0" file="/juno/u/lepertm/shadow/robosuite/robosuite/models/assets/robots/panda/obj_meshes/link7_vis/link7_vis_0.obj" />
	<mesh name="robot0_link7_vis_1" file="/juno/u/lepertm/shadow/robosuite/robosuite/models/assets/robots/panda/obj_meshes/link7_vis/link7_vis_1.obj" />
	<mesh name="robot0_link7_vis_2" file="/juno/u/lepertm/shadow/robosuite/robosuite/models/assets/robots/panda/obj_meshes/link7_vis/link7_vis_2.obj" />
	<mesh name="robot0_link7_vis_3" file="/juno/u/lepertm/shadow/robosuite/robosuite/models/assets/robots/panda/obj_meshes/link7_vis/link7_vis_3.obj" />
	<mesh name="robot0_link7_vis_4" file="/juno/u/lepertm/shadow/robosuite/robosuite/models/assets/robots/panda/obj_meshes/link7_vis/link7_vis_4.obj" />
	<mesh name="robot0_link7_vis_5" file="/juno/u/lepertm/shadow/robosuite/robosuite/models/assets/robots/panda/obj_meshes/link7_vis/link7_vis_5.obj" />
	<mesh name="robot0_link7_vis_6" file="/juno/u/lepertm/shadow/robosuite/robosuite/models/assets/robots/panda/obj_meshes/link7_vis/link7_vis_6.obj" />
	<mesh name="robot0_link7_vis_7" file="/juno/u/lepertm/shadow/robosuite/robosuite/models/assets/robots/panda/obj_meshes/link7_vis/link7_vis_7.obj" />

    <mesh name="mount0_pedestal" file="/juno/u/lepertm/shadow/robosuite/robosuite/models/assets/mounts/meshes/rethink_mount/pedestal.stl" />
    <material name="gripper0_metal" rgba="0.58 0.58 0.58 1" />
    <material name="gripper0_silicone" rgba="0.1882 0.1882 0.1882 1" />
    <material name="gripper0_gray" rgba="0.4627 0.4627 0.4627 1" />
    <material name="gripper0_black" rgba="0.149 0.149 0.149 1" />

    <mesh name="gripper0_base_mount" scale="0.001 0.001 0.001" file="/juno/u/lepertm/shadow/robosuite/robosuite/models/assets/grippers/meshes/robotiq_85_gripper/base_mount.stl" />
    <mesh name="gripper0_base" scale="0.001 0.001 0.001" file="/juno/u/lepertm/shadow/robosuite/robosuite/models/assets/grippers/meshes/robotiq_85_gripper/base.stl" />
    <mesh name="gripper0_driver" scale="0.001 0.001 0.001" file="/juno/u/lepertm/shadow/robosuite/robosuite/models/assets/grippers/meshes/robotiq_85_gripper/driver.stl" />
    <mesh name="gripper0_coupler" scale="0.001 0.001 0.001" file="/juno/u/lepertm/shadow/robosuite/robosuite/models/assets/grippers/meshes/robotiq_85_gripper/coupler.stl" />
    <mesh name="gripper0_follower" scale="0.001 0.001 0.001" file="/juno/u/lepertm/shadow/robosuite/robosuite/models/assets/grippers/meshes/robotiq_85_gripper/follower.stl" />
    <mesh name="gripper0_pad" scale="0.001 0.001 0.001" file="/juno/u/lepertm/shadow/robosuite/robosuite/models/assets/grippers/meshes/robotiq_85_gripper/pad.stl" />
    <mesh name="gripper0_silicone_pad" scale="0.001 0.001 0.001" file="/juno/u/lepertm/shadow/robosuite/robosuite/models/assets/grippers/meshes/robotiq_85_gripper/silicone_pad.stl" />
    <mesh name="gripper0_spring_link" scale="0.001 0.001 0.001" file="/juno/u/lepertm/shadow/robosuite/robosuite/models/assets/grippers/meshes/robotiq_85_gripper/spring_link.stl" />
  </asset>
    <worldbody>
        <body name="robot0_base" pos="0 0 0">
            
            <camera mode="fixed" name="robot0_robotview" pos="1.0 0 0.4" quat="0.653 0.271 0.271 0.653" />
            <inertial diaginertia="0 0 0" mass="0" pos="0 0 0" />
            
            <body name="robot0_link0" pos="0 0 0">
                <inertial pos="0 0 0.05" mass="4" diaginertia="0.4 0.4 0.4" />
		<geom mesh="robot0_link0_vis_0" material="robot0_Shell010_001" type="mesh" contype="0" conaffinity="0" group="1" name="robot0_g0_vis" />
		<geom mesh="robot0_link0_vis_1" material="robot0_Shell009_001" type="mesh" contype="0" conaffinity="0" group="1" name="robot0_g1_vis" />
		<geom mesh="robot0_link0_vis_2" material="robot0_Shell003_001" type="mesh" contype="0" conaffinity="0" group="1" name="robot0_g2_vis" />
		<geom mesh="robot0_link0_vis_3" material="robot0_Shell_001" type="mesh" contype="0" conaffinity="0" group="1" name="robot0_g3_vis" />
		<geom mesh="robot0_link0_vis_4" material="robot0_Shell002_001" type="mesh" contype="0" conaffinity="0" group="1" name="robot0_g4_vis" />
		<geom mesh="robot0_link0_vis_5" material="robot0_Shell001_001" type="mesh" contype="0" conaffinity="0" group="1" name="robot0_g5_vis" />
		<geom mesh="robot0_link0_vis_6" material="robot0_Face636_001" type="mesh" contype="0" conaffinity="0" group="1" name="robot0_g6_vis" />
		<geom mesh="robot0_link0_vis_7" material="robot0_Part__Feature018_001" type="mesh" contype="0" conaffinity="0" group="1" name="robot0_g7_vis" />
		<geom mesh="robot0_link0_vis_8" material="robot0_Part__Feature019_001" type="mesh" contype="0" conaffinity="0" group="1" name="robot0_g8_vis" />
		<geom mesh="robot0_link0_vis_9" material="robot0_Part__Feature023_001" type="mesh" contype="0" conaffinity="0" group="1" name="robot0_g9_vis" />
		<geom mesh="robot0_link0_vis_10" material="robot0_Part__Feature022_001" type="mesh" contype="0" conaffinity="0" group="1" name="robot0_g10_vis" />
		<geom mesh="robot0_link0_vis_11" material="robot0_Part__Feature017_001" type="mesh" contype="0" conaffinity="0" group="1" name="robot0_g11_vis" />

                <geom type="mesh" group="0" mesh="robot0_link0" name="robot0_link0_collision" rgba="0 0.5 0 1" />
                <body name="robot0_link1" pos="0 0 0.333">
                    <inertial pos="0 0 -0.07" mass="3" diaginertia="0.3 0.3 0.3" />
                    <joint name="robot0_joint1" pos="0 0 0" axis="0 0 1" limited="true" range="-2.8973 2.8973" damping="0" frictionloss="0.1" armature="5.0" />
		    <geom material="robot0_Part__Feature_001" mesh="robot0_link1_vis" type="mesh" contype="0" conaffinity="0" group="1" name="robot0_g12_vis" />

                    <geom type="mesh" group="0" mesh="robot0_link1" name="robot0_link1_collision" rgba="0 0.5 0 1" />
                    <body name="robot0_link2" pos="0 0 0" quat="0.707107 -0.707107 0 0">
                        <inertial pos="0 -0.1 0" mass="3" diaginertia="0.3 0.3 0.3" />
                        <joint name="robot0_joint2" pos="0 0 0" axis="0 0 1" limited="true" range="-1.7628 1.7628" damping="0" frictionloss="0.1" armature="2.5" />
			<geom material="robot0_Part__Feature024" mesh="robot0_link2_vis" type="mesh" contype="0" conaffinity="0" group="1" name="robot0_g13_vis" />

                        <geom type="mesh" group="0" mesh="robot0_link2" name="robot0_link2_collision" rgba="0 0.5 0 1" />
                        <body name="robot0_link3" pos="0 -0.316 0" quat="0.707107 0.707107 0 0">
                            <inertial pos="0.04 0 -0.05" mass="2" diaginertia="0.2 0.2 0.2" />
                            <joint name="robot0_joint3" pos="0 0 0" axis="0 0 1" limited="true" range="-2.8973 2.8973" damping="0" frictionloss="0.1" armature="1.6666666666666667" />
			    <geom mesh="robot0_link3_vis_0" material="robot0_Part__Feature003_004_001_002" type="mesh" contype="0" conaffinity="0" group="1" name="robot0_g14_vis" />
			    <geom mesh="robot0_link3_vis_1" material="robot0_Part__Feature002_007_001_002" type="mesh" contype="0" conaffinity="0" group="1" name="robot0_g15_vis" />
			    <geom mesh="robot0_link3_vis_2" material="robot0_Part__Feature001_010_001_002" type="mesh" contype="0" conaffinity="0" group="1" name="robot0_g16_vis" />
			    <geom mesh="robot0_link3_vis_3" material="robot0_Part__Feature_001_001_001_002" type="mesh" contype="0" conaffinity="0" group="1" name="robot0_g17_vis" />
                            <geom type="mesh" group="0" mesh="robot0_link3" name="robot0_link3_collision" rgba="0 0.5 0 1" />
                            <body name="robot0_link4" pos="0.0825 0 0" quat="0.707107 0.707107 0 0">
                                <inertial pos="-0.04 0.05 0" mass="2" diaginertia="0.2 0.2 0.2" />
                                <joint name="robot0_joint4" pos="0 0 0" axis="0 0 1" limited="true" range="-3.0718 -0.0698" damping="0" frictionloss="0.1" armature="1.25" />
				<geom mesh="robot0_link4_vis_0" material="robot0_Part__Feature001_001_003_001" type="mesh" contype="0" conaffinity="0" group="1" name="robot0_g18_vis" />
				<geom mesh="robot0_link4_vis_1" material="robot0_Part__Feature003_001_003_001" type="mesh" contype="0" conaffinity="0" group="1" name="robot0_g19_vis" />
				<geom mesh="robot0_link4_vis_2" material="robot0_Part__Feature002_001_003_001" type="mesh" contype="0" conaffinity="0" group="1" name="robot0_g20_vis" />
				<geom mesh="robot0_link4_vis_3" material="robot0_Part__Feature_002_003_001" type="mesh" contype="0" conaffinity="0" group="1" name="robot0_g21_vis" />

                                <geom type="mesh" group="0" mesh="robot0_link4" name="robot0_link4_collision" rgba="0 0.5 0 1" />
                                <body name="robot0_link5" pos="-0.0825 0.384 0" quat="0.707107 -0.707107 0 0">
                                    <inertial pos="0 0 -0.15" mass="2" diaginertia="0.2 0.2 0.2" />
                                    <joint name="robot0_joint5" pos="0 0 0" axis="0 0 1" limited="true" range="-2.8973 2.8973" damping="0" frictionloss="0.1" armature="1.0" />
				    <geom mesh="robot0_link5_vis_0" material="robot0_Shell001_001_001_003" type="mesh" contype="0" conaffinity="0" group="1" name="robot0_g22_vis" />
				    <geom mesh="robot0_link5_vis_1" material="robot0_Shell_001_001_003" type="mesh" contype="0" conaffinity="0" group="1" name="robot0_g23_vis" />
				    <geom mesh="robot0_link5_vis_2" material="robot0_Part__Feature_002_004_003" type="mesh" contype="0" conaffinity="0" group="1" name="robot0_g24_vis" />

                                    <geom type="mesh" group="0" mesh="robot0_link5" name="robot0_link5_collision" rgba="0 0.5 0 1" />
                                    <body name="robot0_link6" pos="0 0 0" quat="0.707107 0.707107 0 0">
                                        <inertial pos="0.06 0 0" mass="1.5" diaginertia="0.1 0.1 0.1" />
                                        <joint name="robot0_joint6" pos="0 0 0" axis="0 0 1" limited="true" range="-0.0175 3.7525" damping="0" frictionloss="0.1" armature="0.8333333333333334" />
					<geom mesh="robot0_link6_vis_0" material="robot0_Shell006_003_002_001" type="mesh" contype="0" conaffinity="0" group="1" name="robot0_g25_vis" />
					<geom mesh="robot0_link6_vis_1" material="robot0_Shell011_002_002_001" type="mesh" contype="0" conaffinity="0" group="1" name="robot0_g26_vis" />
					<geom mesh="robot0_link6_vis_2" material="robot0_Shell007_002_002_001" type="mesh" contype="0" conaffinity="0" group="1" name="robot0_g27_vis" />
					<geom mesh="robot0_link6_vis_3" material="robot0_Shell005_001_001_002_001" type="mesh" contype="0" conaffinity="0" group="1" name="robot0_g28_vis" />
					<geom mesh="robot0_link6_vis_4" material="robot0_Shell004_001_001_002_001" type="mesh" contype="0" conaffinity="0" group="1" name="robot0_g29_vis" />
					<geom mesh="robot0_link6_vis_5" material="robot0_Shell003_002_001_002_001" type="mesh" contype="0" conaffinity="0" group="1" name="robot0_g30_vis" />
					<geom mesh="robot0_link6_vis_6" material="robot0_Shell002_002_001_002_001" type="mesh" contype="0" conaffinity="0" group="1" name="robot0_g31_vis" />
					<geom mesh="robot0_link6_vis_7" material="robot0_Union001_001_001_002_001" type="mesh" contype="0" conaffinity="0" group="1" name="robot0_g32_vis" />
					<geom mesh="robot0_link6_vis_8" material="robot0_Union_001_001_002_001" type="mesh" contype="0" conaffinity="0" group="1" name="robot0_g33_vis" />
					<geom mesh="robot0_link6_vis_9" material="robot0_Face539_002_001_002_001" type="mesh" contype="0" conaffinity="0" group="1" name="robot0_g34_vis" />
					<geom mesh="robot0_link6_vis_10" material="robot0_Shell_003_001_002_001" type="mesh" contype="0" conaffinity="0" group="1" name="robot0_g35_vis" />
					<geom mesh="robot0_link6_vis_11" material="robot0_Face374_002_001_002_001" type="mesh" contype="0" conaffinity="0" group="1" name="robot0_g36_vis" />
					<geom mesh="robot0_link6_vis_12" material="robot0_Face065_002_001_002_001" type="mesh" contype="0" conaffinity="0" group="1" name="robot0_g37_vis" />
					<geom mesh="robot0_link6_vis_13" material="robot0_Face064_002_001_002_001" type="mesh" contype="0" conaffinity="0" group="1" name="robot0_g38_vis" />
					<geom mesh="robot0_link6_vis_14" material="robot0_Part__Feature002_006_001_002_001" type="mesh" contype="0" conaffinity="0" group="1" name="robot0_g39_vis" />
					<geom mesh="robot0_link6_vis_15" material="robot0_Part__Feature001_009_001_002_001" type="mesh" contype="0" conaffinity="0" group="1" name="robot0_g40_vis" />
					<geom mesh="robot0_link6_vis_16" material="robot0_Shell012_002_002_001" type="mesh" contype="0" conaffinity="0" group="1" name="robot0_g41_vis" />

                                        <geom type="mesh" group="0" mesh="robot0_link6" name="robot0_link6_collision" rgba="0 0.5 0 1" />
                                        <body name="robot0_link7" pos="0.088 0 0" quat="0.707107 0.707107 0 0">
                                            <inertial pos="0 0 0.08" mass="0.5" diaginertia="0.05 0.05 0.05" />
                                            <joint name="robot0_joint7" pos="0 0 0" axis="0 0 1" limited="true" range="-2.8973 2.8973" damping="0" frictionloss="0.1" armature="0.7142857142857143" />
					    <geom mesh="robot0_link7_vis_0" material="robot0_Part__Mirroring004_004_002" type="mesh" contype="0" conaffinity="0" group="1" name="robot0_g42_vis" />
					    <geom mesh="robot0_link7_vis_1" material="robot0_Part__Mirroring001_004_002" type="mesh" contype="0" conaffinity="0" group="1" name="robot0_g43_vis" />
					    <geom mesh="robot0_link7_vis_2" material="robot0_Part__Mirroring007_004_001" type="mesh" contype="0" conaffinity="0" group="1" name="robot0_g44_vis" />
					    <geom mesh="robot0_link7_vis_3" material="robot0_Part__Mirroring006_004_001" type="mesh" contype="0" conaffinity="0" group="1" name="robot0_g45_vis" />
					    <geom mesh="robot0_link7_vis_4" material="robot0_Part__Mirroring005_004_001" type="mesh" contype="0" conaffinity="0" group="1" name="robot0_g46_vis" />
					    <geom mesh="robot0_link7_vis_5" material="robot0_Part__Mirroring003_004_001" type="mesh" contype="0" conaffinity="0" group="1" name="robot0_g47_vis" />
					    <geom mesh="robot0_link7_vis_6" material="robot0_Part__Mirroring002_004_001" type="mesh" contype="0" conaffinity="0" group="1" name="robot0_g48_vis" />
					    <geom mesh="robot0_link7_vis_7" material="robot0_Part__Mirroring_004_001" type="mesh" contype="0" conaffinity="0" group="1" name="robot0_g49_vis" />
                                            
                                            <geom type="mesh" group="0" mesh="robot0_link7" name="robot0_link7_collision" rgba="0 0.5 0 1" />
                                            <body name="robot0_right_hand" pos="0 0 0.1065" quat="0.924 0 0 -0.383">
                                                <inertial pos="0 0 0" mass="0.5" diaginertia="0.05 0.05 0.05" />
                                                
                                                <camera mode="fixed" name="robot0_eye_in_hand" pos="0.05 0 0" quat="0 0.707108 0.707108 0" fovy="75" />
                                                
                                            <body name="gripper0_base_mount" pos="0 0 0.007">
      

    

    
      <site name="gripper0_ft_frame" pos="0 0 0" size="0.01 0.01 0.01" rgba="1 0 0 1" type="sphere" group="1" />
      
      
      <body name="gripper0_eef" pos="0 0 0.14" quat="1 0 0 -1">
        

      

          <site name="gripper0_grip_site" pos="0 0 0" size="0.01 0.01 0.01" rgba="1 0 0 0.5" type="sphere" group="1" />
          <site name="gripper0_ee_x" pos="0.1 0 0" size="0.005 .1" quat="0.707105  0 0.707108 0 " rgba="1 0 0 0" type="cylinder" group="1" />
          <site name="gripper0_ee_y" pos="0 0.1 0" size="0.005 .1" quat="0.707105 0.707108 0 0" rgba="0 1 0 0" type="cylinder" group="1" />
          <site name="gripper0_ee_z" pos="0 0 0.1" size="0.005 .1" quat="1 0 0 0" rgba="0 0 1 0" type="cylinder" group="1" />
          
          <site name="gripper0_grip_site_cylinder" pos="0 0 0" size="0.005 10" rgba="0 1 0 0.3" type="cylinder" group="1" />
      </body>
      
      <geom type="mesh" contype="0" conaffinity="0" group="1" material="gripper0_black" mesh="gripper0_base_mount" name="gripper0_g0_vis" />
      
      <geom mesh="gripper0_base_mount" type="mesh" name="gripper0_g0_col" rgba="0 0 0.5 1" />
      <body name="gripper0_base" pos="0 0 0.0038" quat="0.924 0 0 0.383">
      
        <inertial mass="0.777441" pos="0 -2.70394e-05 0.0354675" quat="1 -0.00152849 0 0" diaginertia="0.000260285 0.000225381 0.000152708" />
        
        <geom type="mesh" contype="0" conaffinity="0" group="1" material="gripper0_black" mesh="gripper0_base" name="gripper0_g1_vis" />
        
        <geom mesh="gripper0_base" type="mesh" name="gripper0_g1_col" rgba="0 0 0.5 1" />
        <site name="gripper0_pinch" pos="0 0 0.145" type="sphere" group="5" rgba="0.9 0.9 0.9 1" size="0.005" />
        
        <body name="gripper0_right_driver" pos="0 0.0306011 0.054904">
          <inertial mass="0.00899563" pos="2.96931e-12 0.0177547 0.00107314" quat="0.681301 0.732003 0 0" diaginertia="1.72352e-06 1.60906e-06 3.22006e-07" />
            
          <joint name="gripper0_right_driver_joint" axis="1 0 0" range="0 0.8" armature="0.005" damping="0.1" solimplimit="0.95 0.99 0.001" solreflimit="0.005 1" />
          
          <geom type="mesh" contype="0" conaffinity="0" group="1" material="gripper0_gray" mesh="gripper0_driver" name="gripper0_g2_vis" />
          
            <geom mesh="gripper0_driver" type="mesh" name="gripper0_g2_col" rgba="0 0 0.5 1" />
          <body name="gripper0_right_coupler" pos="0 0.0315 -0.0041">
            <inertial mass="0.0140974" pos="0 0.00301209 0.0232175" quat="0.705636 -0.0455904 0.0455904 0.705636" diaginertia="4.16206e-06 3.52216e-06 8.88131e-07" />
            
            <joint name="gripper0_right_coupler_joint" axis="1 0 0" range="-1.57 0" armature="0.001" solimplimit="0.95 0.99 0.001" solreflimit="0.005 1" />
            
            <geom type="mesh" contype="0" conaffinity="0" group="1" material="gripper0_black" mesh="gripper0_coupler" name="gripper0_g3_vis" />
            
                <geom mesh="gripper0_coupler" type="mesh" name="gripper0_g3_col" rgba="0 0 0.5 1" />
          </body>
        </body>
        <body name="gripper0_right_spring_link" pos="0 0.0132 0.0609">
          <inertial mass="0.0221642" pos="-8.65005e-09 0.0181624 0.0212658" quat="0.663403 -0.244737 0.244737 0.663403" diaginertia="8.96853e-06 6.71733e-06 2.63931e-06" />
            
          <joint name="gripper0_right_spring_link_joint" axis="1 0 0" range="-0.29670597283 0.8" armature="0.001" stiffness="0.05" springref="2.62" damping="0.00125" />
          
          <geom type="mesh" contype="0" conaffinity="0" group="1" material="gripper0_black" mesh="gripper0_spring_link" name="gripper0_g4_vis" />
          
            <geom mesh="gripper0_spring_link" type="mesh" name="gripper0_g4_col" rgba="0 0 0.5 1" />
          <body name="gripper0_right_follower" pos="0 0.055 0.0375">
            <inertial mass="0.0125222" pos="0 -0.011046 0.0124786" quat="1 0.1664 0 0" diaginertia="2.67415e-06 2.4559e-06 6.02031e-07" />
            
            <joint name="gripper0_right_follower_joint" axis="1 0 0" range="-0.872664 0.872664" armature="0.001" pos="0 -0.018 0.0065" solimplimit="0.95 0.99 0.001" solreflimit="0.005 1" />
            
            <geom type="mesh" contype="0" conaffinity="0" group="1" material="gripper0_black" mesh="gripper0_follower" name="gripper0_g5_vis" />
            
            <geom mesh="gripper0_follower" type="mesh" name="gripper0_g5_col" rgba="0 0 0.5 1" />

            <body name="gripper0_right_pad" pos="0 -0.0189 0.01352">
              
              <geom name="gripper0_right_pad1" mass="0" type="box" pos="0 -0.0026 0.028125" size="0.011 0.004 0.009375" friction="0.7" solimp="0.95 0.99 0.001" solref="0.004 1" priority="1" rgba="0 0 0.5 1" /> 
              
              <geom name="gripper0_right_pad2" mass="0" type="box" pos="0 -0.0026 0.009375" size="0.011 0.004 0.009375" friction="0.6" solimp="0.95 0.99 0.001" solref="0.004 1" priority="1" rgba="0 0 0.5 1" />
              <inertial mass="0.0035" pos="0 -0.0025 0.0185" quat="0.707107 0 0 0.707107" diaginertia="4.73958e-07 3.64583e-07 1.23958e-07" />
              
              <geom type="mesh" contype="0" conaffinity="0" group="1" mesh="gripper0_pad" name="gripper0_g6_vis" />

              <body name="gripper0_right_silicone_pad">
                
                <geom type="mesh" contype="0" conaffinity="0" group="1" material="gripper0_black" mesh="gripper0_silicone_pad" name="gripper0_g7_vis" />

              </body>
            </body>
          </body>
        </body>
        
        <body name="gripper0_left_driver" pos="0 -0.0306011 0.054904" quat="0 0 0 1">
          <inertial mass="0.00899563" pos="0 0.0177547 0.00107314" quat="0.681301 0.732003 0 0" diaginertia="1.72352e-06 1.60906e-06 3.22006e-07" />
          <joint name="gripper0_left_driver_joint" axis="1 0 0" range="0 0.8" armature="0.005" damping="0.1" solimplimit="0.95 0.99 0.001" solreflimit="0.005 1" />
          
          
          <geom type="mesh" contype="0" conaffinity="0" group="1" material="gripper0_gray" mesh="gripper0_driver" name="gripper0_g8_vis" />
          
            <geom mesh="gripper0_driver" type="mesh" name="gripper0_g6_col" rgba="0 0 0.5 1" />
          <body name="gripper0_left_coupler" pos="0 0.0315 -0.0041">
            <inertial mass="0.0140974" pos="0 0.00301209 0.0232175" quat="0.705636 -0.0455904 0.0455904 0.705636" diaginertia="4.16206e-06 3.52216e-06 8.88131e-07" />
            
            <joint name="gripper0_left_coupler_joint" axis="1 0 0" range="-1.57 0" armature="0.001" solimplimit="0.95 0.99 0.001" solreflimit="0.005 1" />
            
            <geom type="mesh" contype="0" conaffinity="0" group="1" material="gripper0_black" mesh="gripper0_coupler" name="gripper0_g9_vis" />
            
            <geom mesh="gripper0_coupler" type="mesh" name="gripper0_g7_col" rgba="0 0 0.5 1" />
          </body>
        </body>
        <body name="gripper0_left_spring_link" pos="0 -0.0132 0.0609" quat="0 0 0 1">
          <inertial mass="0.0221642" pos="-8.65005e-09 0.0181624 0.0212658" quat="0.663403 -0.244737 0.244737 0.663403" diaginertia="8.96853e-06 6.71733e-06 2.63931e-06" />
            
          <joint name="gripper0_left_spring_link_joint" axis="1 0 0" range="-0.29670597283 0.8" armature="0.001" stiffness="0.05" springref="2.62" damping="0.00125" />
          
          <geom type="mesh" contype="0" conaffinity="0" group="1" material="gripper0_black" mesh="gripper0_spring_link" name="gripper0_g10_vis" />
          
            <geom mesh="gripper0_spring_link" type="mesh" name="gripper0_g8_col" rgba="0 0 0.5 1" />
          <body name="gripper0_left_follower" pos="0 0.055 0.0375">
            <inertial mass="0.0125222" pos="0 -0.011046 0.0124786" quat="1 0.1664 0 0" diaginertia="2.67415e-06 2.4559e-06 6.02031e-07" />
            
            <joint name="gripper0_left_follower_joint" axis="1 0 0" range="-0.872664 0.872664" armature="0.001" pos="0 -0.018 0.0065" solimplimit="0.95 0.99 0.001" solreflimit="0.005 1" />
            
            <geom type="mesh" contype="0" conaffinity="0" group="1" material="gripper0_black" mesh="gripper0_follower" name="gripper0_g11_vis" />
            
            <geom mesh="gripper0_follower" type="mesh" name="gripper0_g9_col" rgba="0 0 0.5 1" />
            <body name="gripper0_left_pad" pos="0 -0.0189 0.01352">
              
              <geom mass="0" type="box" pos="0 -0.0026 0.028125" size="0.011 0.004 0.009375" friction="0.7" solimp="0.95 0.99 0.001" solref="0.004 1" priority="1" rgba="0 0 0.5 1" name="gripper0_g10_col" />
              
              <geom mass="0" type="box" pos="0 -0.0026 0.009375" size="0.011 0.004 0.009375" friction="0.6" solimp="0.95 0.99 0.001" solref="0.004 1" priority="1" rgba="0 0 0.5 1" name="gripper0_g11_col" />
              <inertial mass="0.0035" pos="0 -0.0025 0.0185" quat="1 0 0 1" diaginertia="4.73958e-07 3.64583e-07 1.23958e-07" />
              
              <geom type="mesh" contype="0" conaffinity="0" group="1" mesh="gripper0_pad" name="gripper0_g12_vis" />
                <body name="gripper0_left_silicone_pad">
                  
                  <geom type="mesh" contype="0" conaffinity="0" group="1" material="gripper0_black" mesh="gripper0_silicone_pad" name="gripper0_g13_vis" />
                </body>
            </body>
          </body>
        </body>
      </body>
    </body>
  </body>
                                        </body>
                                    </body>
                                </body>
                            </body>
                        </body>
                    </body>
                </body>
            </body>
        <body name="mount0_base" pos="0.0 0.0 0.01">
            <body name="mount0_controller_box" pos="0 0 0">
                <inertial diaginertia="1.71363 1.27988 0.809981" mass="46.64" pos="-0.325 0 -0.38" />
                <geom pos="-0.325 0 -0.38" size="0.11 0.2 0.265" type="box" name="mount0_controller_box_col" rgba="0.5 0.5 0 1" />
            </body>
            <body name="mount0_pedestal_feet" pos="0 0 0">
                <inertial diaginertia="8.16095 9.59375 15.0785" mass="167.09" pos="-0.1225 0 -0.758" />
                <geom pos="-0.1225 0 -0.758" size="0.385 0.35 0.155" type="box" name="mount0_pedestal_feet_col" rgba="0.5 0.5 0 1" />
            </body>
            <body name="mount0_torso" pos="0 0 0">
                <inertial diaginertia="1e-08 1e-08 1e-08" mass="0.0001" pos="0 0 0" />
                <geom conaffinity="0" contype="0" group="1" pos="0 0 -0.05" size="0.05 0.05 0.05" type="box" name="mount0_torso_vis" rgba="0.2 0.2 0.2 1" />
            </body>
            <body name="mount0_pedestal" pos="0 0 0">
                <inertial diaginertia="6.0869 5.81635 4.20915" mass="60.864" pos="0 0 0" quat="0.659267 -0.259505 -0.260945 0.655692" />
                <geom conaffinity="0" contype="0" group="1" mesh="mount0_pedestal" type="mesh" name="mount0_pedestal_vis" rgba="0.2 0.2 0.2 1" />
                <geom pos="-0.02 0 -0.29" rgba="0.5 0.5 0 1" size="0.18 0.31" type="cylinder" name="mount0_pedestal_col" />
            </body>
        </body>
    </body>
    </worldbody>
<sensor><force name="gripper0_force_ee" site="gripper0_ft_frame" />
      <torque name="gripper0_torque_ee" site="gripper0_ft_frame" />
  </sensor><tendon><fixed name="gripper0_split">
      <joint joint="gripper0_right_driver_joint" coef="0.5" />
      <joint joint="gripper0_left_driver_joint" coef="0.5" />
    </fixed>
  </tendon><equality><connect anchor="0 0 0" body1="gripper0_right_follower" body2="gripper0_right_coupler" solimp="0.95 0.99 0.001" solref="0.005 1" />
    <connect anchor="0 0 0" body1="gripper0_left_follower" body2="gripper0_left_coupler" solimp="0.95 0.99 0.001" solref="0.005 1" />
    <joint joint1="gripper0_right_driver_joint" joint2="gripper0_left_driver_joint" polycoef="0 1 0 0 0" solimp="0.95 0.99 0.001" solref="0.005 1" />
  </equality><contact><exclude body1="gripper0_base" body2="gripper0_left_driver" />
    <exclude body1="gripper0_base" body2="gripper0_right_driver" />
    <exclude body1="gripper0_base" body2="gripper0_left_spring_link" />
    <exclude body1="gripper0_base" body2="gripper0_right_spring_link" />
    <exclude body1="gripper0_right_coupler" body2="gripper0_right_follower" />
    <exclude body1="gripper0_left_coupler" body2="gripper0_left_follower" />
  </contact></mujoco>